<?xml version="1.0" encoding="utf-8"?>
<mujoco model="quadruped_torso">
  <compiler angle="radian" inertiafromgeom="true" coordinate="local" />
  <option timestep="0.01" gravity="0 0 -9.81" />
  <worldbody>
    <geom name="floor" type="plane" size="2 2 0.1" pos="0 0 -0.5" rgba="6 0.9 0.9 1" />
    <body name="torso" pos="0 0 0.32" quat="1 0 0 0">
      <geom name="torso_body" type="box" size="0.5 0.15 0.1" rgba="0.8 0.2 0.2 1" />
      <inertial pos="0 0 0" mass="2.0" diaginertia="0.1 0.2 0.1" />
      <body name="leg_front_right" pos="0.25 0.15 0">
        <geom name="G_vis0_front_right" type="box" rgba="0.1568627450980392 0.42745098039215684 0.8 1.0" contype="1" conaffinity="1" pos="0.0 0.0 0.0" quat="1.0 0.0 0.0 0.0" size="0.0335 0.0335 0.0335" />
        <inertial pos="0.0 0.0 0.0" mass="0.04903493747122909" diaginertia="3.66863057180579e-05 3.66863057180579e-05 3.66863057180579e-05" />
        <body name="L3_front_right" pos="0.0 0.0 0.0" quat="0.07437622984429398 5.650851124421949e-17 0.9972302524663743 5.650851124421949e-17">
          <joint name="Main_ground_front_right" type="hinge" axis="0 1 0" range="-3.141592653589793 3.141592653589793" damping="0.1" />
          <geom name="L3_vis0_front_right" type="box" rgba="0.37254901960784315 0.5019607843137255 0.8352941176470589 1.0" contype="1" conaffinity="1" pos="6.1321225795853815e-18 0.0 0.3057830760522891" quat="1.0 0.0 0.0 0.0" size="0.016750000417232513 0.016750000417232513 0.041494395021298744" />
          <geom name="L3_vis1_front_right" type="box" rgba="0.37254901960784315 0.5019607843137255 0.8352941176470589 1.0" contype="1" conaffinity="1" pos="3.974438985929238e-18 0.0 0.12376934030687893" quat="1.0 0.0 0.0 0.0" size="0.016750000417232513 0.016750000417232513 0.10701933988964642" />
          <geom name="L3_vis2_front_right" type="box" rgba="0.37254901960784315 0.5019607843137255 0.8352941176470589 1.0" contype="1" conaffinity="1" pos="2.1576835936561436e-18 0.0 0.1820137357454102" quat="1.0 0.0 0.0 0.0" size="0.016750000417232513 0.016750000417232513 0.16526373532817767" />
          <inertial pos="0.0 0.0 0.20386" mass="0.29536707186095634" diaginertia="0.046740090156920405 0.04702657912522108 0.0003417349201298814" />
          <body name="L4_front_right" pos="4.315367187312287e-18 0.0 0.3640274714908204" quat="0.9889363528682975 0.0 0.14834045293024475 0.0">
            <joint name="Main_knee_front_right" type="hinge" axis="0 1 0" range="-3.141592653589793 3.141592653589793" damping="0.1" />
            <geom name="L4_vis0_front_right" type="box" rgba="0.5176470588235295 0.5843137254901961 0.8705882352941177 1.0" contype="1" conaffinity="1" pos="0.025481923004357435 0.0 0.26938032890320707" quat="0.13111872764660734 5.267499460431457e-17 0.9913666724579432 5.267499460431457e-17" size="0.016750000417232513 0.016750000417232513 0.08126739599789375" />
            <geom name="L4_vis1_front_right" type="box" rgba="0.5176470588235295 0.5843137254901961 0.8705882352941177 1.0" contype="1" conaffinity="1" pos="6.938893903907228e-18 0.0 0.1820137357454102" quat="1.0 0.0 0.0 0.0" size="0.016750000417232513 0.016750000417232513 0.16526373532817767" />
            <geom name="L4_vis2_front_right" type="box" rgba="0.5176470588235295 0.5843137254901961 0.8705882352941177 1.0" contype="1" conaffinity="1" pos="0.02548192300435744 0.0 0.08736659315779688" quat="0.1414213562373094 -5.195736337412961e-17 -0.9899494936611666 5.195736337412961e-17" size="0.016750000417232513 0.016750000417232513 0.07425686745547257" />
            <inertial pos="0.01699 0.0 0.17959" mass="0.5012590142024277" diaginertia="0.2619561188565024 0.26221491311633094 0.0003525505859475547" />
            <body name="EE_front_right" pos="0.0 0.0 0.3640274714908204" quat="0.07437622984429398 5.650851124421949e-17 0.9972302524663743 5.650851124421949e-17">
              <geom name="EE_vis0_front_right" type="sphere" rgba="0.6431372549019608 0.6666666666666666 0.9058823529411765 1.0" contype="1" conaffinity="1" pos="0.0 0.0 0.0" quat="1.0 0.0 0.0 0.0" size="0.002142857142857143" />
              <inertial pos="0.0 0.0 0.0" mass="2.979933439782622e-05" diaginertia="5.473347134294612e-11 5.473347134294612e-11 5.473347134294612e-11" />
            </body>
            <body name="Main_ee_L4Unit_front_right" pos="0.0 0.0 0.3640274714908204" quat="0.0525919364819896 0.0525919364819895 0.7051482739233461 -0.705148273923346">
              <geom name="Main_ee_L4Unit_vis0_front_right" type="cylinder" rgba="0.5176470588235295 0.5843137254901961 0.8705882352941177 0.9" contype="1" conaffinity="1" size="0.016 0.015" />
              <inertial pos="0 0 0" mass="0.1" diaginertia="0.00065 0.00065 0.0008" />
            </body>
            <body name="Main_connection_2_L4Pseudo_front_right" pos="0.05096384600871484 0.0 0.17473318631559376" quat="0.8980331588121276 0.0 -0.4399277732468274 0.0">
              <geom name="Main_connection_2_L4Pseudo_vis0_front_right" type="sphere" rgba="0.5176470588235295 0.5843137254901961 0.8705882352941177 0.5" contype="1" conaffinity="1" size="0.02392857202461788" />
              <inertial pos="0 0 0" mass="0.05" diaginertia="1.145153118274651e-05 1.145153118274651e-05 1.145153118274651e-05" />
            </body>
          </body>
          <body name="Main_knee_L3Unit_front_right" pos="4.315367187312287e-18 0.0 0.3640274714908204" quat="0.6992836012750656 0.6992836012750655 0.10489254019125986 -0.10489254019125985">
            <geom name="Main_knee_L3Unit_vis0_front_right" type="cylinder" rgba="0.37254901960784315 0.5019607843137255 0.8352941176470589 0.9" contype="1" conaffinity="1" size="0.016 0.015" />
            <inertial pos="0 0 0" mass="0.1" diaginertia="0.00065 0.00065 0.0008" />
          </body>
          <body name="L8_front_right" pos="7.948877971858476e-18 0.0 0.24753868061375786" quat="0.8807107787388322 0.0 0.47365443544132435 0.0">
            <joint name="Main_connection_1_front_right" type="hinge" axis="0 1 0" range="-3.141592653589793 3.141592653589793" damping="0.1" />
            <geom name="L8_vis0_front_right" type="box" rgba="0.01568627450980392 0.5058823529411764 0.29411764705882354 1.0" contype="1" conaffinity="1" pos="-0.0 0.0 0.1009" quat="1.0 0.0 0.0 0.0" size="0.01675 0.01675 0.08415218035305282" />
            <inertial pos="-0.0 0.0 0.1009" mass="0.13655992824415478" diaginertia="0.0003351249810435438 0.0003351249810435438 2.554239657866712e-05" />
            <body name="branch_0_L8Pseudo_front_right" pos="0.0 0.0 0.20180436070610566" quat="-0.6966608812115375 8.658629315504744e-17 0.717400597009484 8.658629315504744e-17">
              <geom name="branch_0_L8Pseudo_vis0_front_right" type="sphere" rgba="0.01568627450980392 0.5058823529411764 0.29411764705882354 0.5" contype="1" conaffinity="1" size="0.02392857142857143" />
              <inertial pos="0 0 0" mass="0.05" diaginertia="1.1451530612244902e-05 1.1451530612244902e-05 1.1451530612244902e-05" />
            </body>
          </body>
          <body name="Main_connection_1_L3Unit_front_right" pos="7.948877971858476e-18 0.0 0.24753868061375786" quat="0.6227565639103132 0.6227565639103133 0.33492426323964625 -0.3349242632396462">
            <geom name="Main_connection_1_L3Unit_vis0_front_right" type="cylinder" rgba="0.37254901960784315 0.5019607843137255 0.8352941176470589 0.9" contype="1" conaffinity="1" size="0.016 0.015" />
            <inertial pos="0 0 0" mass="0.1" diaginertia="0.00065 0.00065 0.0008" />
          </body>
        </body>
        <body name="Main_ground_GActuator_front_right" pos="0.0 0.03675000041723252 0.0" quat="0.0525919364819896 0.0525919364819895 0.7051482739233461 -0.705148273923346">
          <geom name="Main_ground_GActuator_vis0_front_right" type="cylinder" rgba="0.1568627450980392 0.42745098039215684 0.8 0.9" contype="1" conaffinity="1" size="0.048 0.02" />
          <inertial pos="0 0 0" mass="0.44" diaginertia="0.0067466666666666664 0.0067466666666666664 0.01056" />
        </body>
        <body name="Main_ground_GUnit_front_right" pos="0.0 0.0 0.0" quat="0.0525919364819896 0.0525919364819895 0.7051482739233461 -0.705148273923346">
          <geom name="Main_ground_GUnit_vis0_front_right" type="cylinder" rgba="0.1568627450980392 0.42745098039215684 0.8 0.9" contype="1" conaffinity="1" size="0.016750000417232513 0.016750000417232513" />
          <inertial pos="0 0 0" mass="0.1" diaginertia="0.0006979166840513548 0.0006979166840513548 0.0008375000208616257" />
        </body>
        <body name="L7_front_right" pos="-0.18000000000000002 0.0 0.06480000000000001" quat="-0.15086421372374947 6.976927370879126e-17 0.9885544947131214 6.976927370879126e-17">
          <joint name="Ground_connection_front_right" type="hinge" axis="0 1 0" range="-3.141592653589793 3.141592653589793" damping="0.1" />
          <geom name="L7_vis0_front_right" type="box" rgba="0.0 1.0 0.4666666666666667 1.0" contype="1" conaffinity="1" pos="-0.0 0.0 0.07543" quat="1.0 0.0 0.0 0.0" size="0.01675 0.01675 0.05868374576408096" />
          <inertial pos="-0.0 0.0 0.07543" mass="0.09523042750668785" diaginertia="0.00011822364017562971 0.00011822364017562971 1.7812057878230073e-05" />
          <body name="L6_front_right" pos="-5.551115123125783e-17 0.0 0.15086749152816192" quat="0.9908668077066263 0.0 -0.13484424120176491 0.0">
            <joint name="branch_2_front_right" type="hinge" axis="0 1 0" range="-3.141592653589793 3.141592653589793" damping="0.1" />
            <geom name="L6_vis0_front_right" type="box" rgba="0.0 0.8274509803921568 0.4196078431372549 1.0" contype="1" conaffinity="1" pos="0.0 0.0 0.11308" quat="1.0 0.0 0.0 0.0" size="0.01675 0.01675 0.09632924654860417" />
            <inertial pos="0.0 0.0 0.11308" mass="0.15632054857404132" diaginertia="0.0004981355538131413 0.0004981355538131413 2.9238455939536312e-05" />
            <body name="L5_front_right" pos="1.1102230246251565e-16 0.0 0.2261584930972083" quat="0.9221247588124448 0.0 -0.3868926584791841 0.0">
              <joint name="branch_1_front_right" type="hinge" axis="0 1 0" range="-3.141592653589793 3.141592653589793" damping="0.1" />
              <geom name="L5_vis0_front_right" type="box" rgba="0.0 0.6627450980392157 0.3607843137254902 1.0" contype="1" conaffinity="1" pos="-0.017313186151101806 0.0 0.22013287438567025" quat="0.9948405908123037 0.0 0.10145047497289715 0.0" size="0.016750000417232513 0.016750000417232513 0.06902079181415591" />
              <geom name="L5_vis1_front_right" type="box" rgba="0.0 0.6627450980392157 0.3607843137254902 1.0" contype="1" conaffinity="1" pos="-0.017313186151101806 0.0 0.06806381112821479" quat="0.12422055223167687 5.315175785701328e-17 0.9922546318376434 5.315175785701328e-17" size="0.016750000417232513 0.016750000417232513 0.053481251885428294" />
              <geom name="L5_vis2_front_right" type="box" rgba="0.0 0.6627450980392157 0.3607843137254902 1.0" contype="1" conaffinity="1" pos="0.0 0.0 0.15206906325745548" quat="1.0 0.0 0.0 0.0" size="0.016750000417232513 0.016750000417232513 0.13531906284022296" />
              <inertial pos="-0.01154 0.0 0.14676" mass="0.37744913378400663" diaginertia="0.11719219359867927 0.12293904243849035 0.005817447558393084" />
              <body name="branch_0_L5Pseudo_front_right" pos="-0.03462637230220361 0.0 0.13612762225642958" quat="1.0 0.0 0.0 0.0">
                <joint name="branch_0_L5_revolute_front_right" type="hinge" axis="0 1 0" range="-3.141592653589793 3.141592653589793" damping="0.1" />
                <geom name="branch_0_L5Pseudo_vis0_front_right" type="sphere" rgba="0.0 0.6627450980392157 0.3607843137254902 0.5" contype="1" conaffinity="1" size="0.02392857202461788" />
                <inertial pos="0 0 0" mass="0.05" diaginertia="1.145153118274651e-05 1.145153118274651e-05 1.145153118274651e-05" />
              </body>
              <body name="Main_connection_2_L5Pseudo_front_right" pos="0.0 0.0 0.30413812651491096" quat="1.0 0.0 0.0 0.0">
                <joint name="Main_connection_2_L5_revolute_front_right" type="hinge" axis="0 1 0" range="-3.141592653589793 3.141592653589793" damping="0.1" />
                <geom name="Main_connection_2_L5Pseudo_vis0_front_right" type="sphere" rgba="0.0 0.6627450980392157 0.3607843137254902 0.5" contype="1" conaffinity="1" size="0.02392857202461788" />
                <inertial pos="0 0 0" mass="0.05" diaginertia="1.145153118274651e-05 1.145153118274651e-05 1.145153118274651e-05" />
              </body>
            </body>
            <body name="branch_1_L6Unit_front_right" pos="1.1102230246251565e-16 0.0 0.2261584930972083" quat="0.6520406700562894 0.6520406700562893 -0.27357442240192215 0.273574422401922">
              <geom name="branch_1_L6Unit_vis0_front_right" type="cylinder" rgba="0.0 0.8274509803921568 0.4196078431372549 0.9" contype="1" conaffinity="1" size="0.016 0.015" />
              <inertial pos="0 0 0" mass="0.1" diaginertia="0.00065 0.00065 0.0008" />
            </body>
          </body>
          <body name="branch_2_L7Unit_front_right" pos="-5.551115123125783e-17 0.0 0.15086749152816192" quat="0.7006486389820223 0.7006486389820222 -0.09534927735772235 0.09534927735772233">
            <geom name="branch_2_L7Unit_vis0_front_right" type="cylinder" rgba="0.0 1.0 0.4666666666666667 0.9" contype="1" conaffinity="1" size="0.016 0.015" />
            <inertial pos="0 0 0" mass="0.1" diaginertia="0.00065 0.00065 0.0008" />
          </body>
        </body>
        <body name="Ground_connection_GActuator_front_right" pos="-0.18000000000000002 0.036750000000000005 0.06480000000000001" quat="-0.10667710856243973 -0.10667710856243982 0.6990135867840891 -0.6990135867840892">
          <geom name="Ground_connection_GActuator_vis0_front_right" type="cylinder" rgba="0.1568627450980392 0.42745098039215684 0.8 0.9" contype="1" conaffinity="1" size="0.048 0.02" />
          <inertial pos="0 0 0" mass="0.44" diaginertia="0.0067466666666666664 0.0067466666666666664 0.01056" />
        </body>
        <body name="Ground_connection_GUnit_front_right" pos="-0.18000000000000002 0.0 0.06480000000000001" quat="-0.10667710856243973 -0.10667710856243982 0.6990135867840891 -0.6990135867840892">
          <geom name="Ground_connection_GUnit_vis0_front_right" type="cylinder" rgba="0.1568627450980392 0.42745098039215684 0.8 0.9" contype="1" conaffinity="1" size="0.01675 0.01675" />
          <inertial pos="0 0 0" mass="0.1" diaginertia="0.0006979166666666668 0.0006979166666666668 0.0008375000000000001" />
        </body>
      </body>
      <body name="leg_front_left" pos="0.25 -0.15 0">
        <geom name="G_vis0_front_left" type="box" rgba="0.1568627450980392 0.42745098039215684 0.8 1.0" contype="1" conaffinity="1" pos="0.0 0.0 0.0" quat="1.0 0.0 0.0 0.0" size="0.0335 0.0335 0.0335" />
        <inertial pos="0.0 0.0 0.0" mass="0.04903493747122909" diaginertia="3.66863057180579e-05 3.66863057180579e-05 3.66863057180579e-05" />
        <body name="L3_front_left" pos="0.0 0.0 0.0" quat="0.07437622984429398 5.650851124421949e-17 0.9972302524663743 5.650851124421949e-17">
          <joint name="Main_ground_front_left" type="hinge" axis="0 1 0" range="-3.141592653589793 3.141592653589793" damping="0.1" />
          <geom name="L3_vis0_front_left" type="box" rgba="0.37254901960784315 0.5019607843137255 0.8352941176470589 1.0" contype="1" conaffinity="1" pos="6.1321225795853815e-18 0.0 0.3057830760522891" quat="1.0 0.0 0.0 0.0" size="0.016750000417232513 0.016750000417232513 0.041494395021298744" />
          <geom name="L3_vis1_front_left" type="box" rgba="0.37254901960784315 0.5019607843137255 0.8352941176470589 1.0" contype="1" conaffinity="1" pos="3.974438985929238e-18 0.0 0.12376934030687893" quat="1.0 0.0 0.0 0.0" size="0.016750000417232513 0.016750000417232513 0.10701933988964642" />
          <geom name="L3_vis2_front_left" type="box" rgba="0.37254901960784315 0.5019607843137255 0.8352941176470589 1.0" contype="1" conaffinity="1" pos="2.1576835936561436e-18 0.0 0.1820137357454102" quat="1.0 0.0 0.0 0.0" size="0.016750000417232513 0.016750000417232513 0.16526373532817767" />
          <inertial pos="0.0 0.0 0.20386" mass="0.29536707186095634" diaginertia="0.046740090156920405 0.04702657912522108 0.0003417349201298814" />
          <body name="L4_front_left" pos="4.315367187312287e-18 0.0 0.3640274714908204" quat="0.9889363528682975 0.0 0.14834045293024475 0.0">
            <joint name="Main_knee_front_left" type="hinge" axis="0 1 0" range="-3.141592653589793 3.141592653589793" damping="0.1" />
            <geom name="L4_vis0_front_left" type="box" rgba="0.5176470588235295 0.5843137254901961 0.8705882352941177 1.0" contype="1" conaffinity="1" pos="0.025481923004357435 0.0 0.26938032890320707" quat="0.13111872764660734 5.267499460431457e-17 0.9913666724579432 5.267499460431457e-17" size="0.016750000417232513 0.016750000417232513 0.08126739599789375" />
            <geom name="L4_vis1_front_left" type="box" rgba="0.5176470588235295 0.5843137254901961 0.8705882352941177 1.0" contype="1" conaffinity="1" pos="6.938893903907228e-18 0.0 0.1820137357454102" quat="1.0 0.0 0.0 0.0" size="0.016750000417232513 0.016750000417232513 0.16526373532817767" />
            <geom name="L4_vis2_front_left" type="box" rgba="0.5176470588235295 0.5843137254901961 0.8705882352941177 1.0" contype="1" conaffinity="1" pos="0.02548192300435744 0.0 0.08736659315779688" quat="0.1414213562373094 -5.195736337412961e-17 -0.9899494936611666 5.195736337412961e-17" size="0.016750000417232513 0.016750000417232513 0.07425686745547257" />
            <inertial pos="0.01699 0.0 0.17959" mass="0.5012590142024277" diaginertia="0.2619561188565024 0.26221491311633094 0.0003525505859475547" />
            <body name="EE_front_left" pos="0.0 0.0 0.3640274714908204" quat="0.07437622984429398 5.650851124421949e-17 0.9972302524663743 5.650851124421949e-17">
              <geom name="EE_vis0_front_left" type="sphere" rgba="0.6431372549019608 0.6666666666666666 0.9058823529411765 1.0" contype="1" conaffinity="1" pos="0.0 0.0 0.0" quat="1.0 0.0 0.0 0.0" size="0.002142857142857143" />
              <inertial pos="0.0 0.0 0.0" mass="2.979933439782622e-05" diaginertia="5.473347134294612e-11 5.473347134294612e-11 5.473347134294612e-11" />
            </body>
            <body name="Main_ee_L4Unit_front_left" pos="0.0 0.0 0.3640274714908204" quat="0.0525919364819896 0.0525919364819895 0.7051482739233461 -0.705148273923346">
              <geom name="Main_ee_L4Unit_vis0_front_left" type="cylinder" rgba="0.5176470588235295 0.5843137254901961 0.8705882352941177 0.9" contype="1" conaffinity="1" size="0.016 0.015" />
              <inertial pos="0 0 0" mass="0.1" diaginertia="0.00065 0.00065 0.0008" />
            </body>
            <body name="Main_connection_2_L4Pseudo_front_left" pos="0.05096384600871484 0.0 0.17473318631559376" quat="0.8980331588121276 0.0 -0.4399277732468274 0.0">
              <geom name="Main_connection_2_L4Pseudo_vis0_front_left" type="sphere" rgba="0.5176470588235295 0.5843137254901961 0.8705882352941177 0.5" contype="1" conaffinity="1" size="0.02392857202461788" />
              <inertial pos="0 0 0" mass="0.05" diaginertia="1.145153118274651e-05 1.145153118274651e-05 1.145153118274651e-05" />
            </body>
          </body>
          <body name="Main_knee_L3Unit_front_left" pos="4.315367187312287e-18 0.0 0.3640274714908204" quat="0.6992836012750656 0.6992836012750655 0.10489254019125986 -0.10489254019125985">
            <geom name="Main_knee_L3Unit_vis0_front_left" type="cylinder" rgba="0.37254901960784315 0.5019607843137255 0.8352941176470589 0.9" contype="1" conaffinity="1" size="0.016 0.015" />
            <inertial pos="0 0 0" mass="0.1" diaginertia="0.00065 0.00065 0.0008" />
          </body>
          <body name="L8_front_left" pos="7.948877971858476e-18 0.0 0.24753868061375786" quat="0.8807107787388322 0.0 0.47365443544132435 0.0">
            <joint name="Main_connection_1_front_left" type="hinge" axis="0 1 0" range="-3.141592653589793 3.141592653589793" damping="0.1" />
            <geom name="L8_vis0_front_left" type="box" rgba="0.01568627450980392 0.5058823529411764 0.29411764705882354 1.0" contype="1" conaffinity="1" pos="-0.0 0.0 0.1009" quat="1.0 0.0 0.0 0.0" size="0.01675 0.01675 0.08415218035305282" />
            <inertial pos="-0.0 0.0 0.1009" mass="0.13655992824415478" diaginertia="0.0003351249810435438 0.0003351249810435438 2.554239657866712e-05" />
            <body name="branch_0_L8Pseudo_front_left" pos="0.0 0.0 0.20180436070610566" quat="-0.6966608812115375 8.658629315504744e-17 0.717400597009484 8.658629315504744e-17">
              <geom name="branch_0_L8Pseudo_vis0_front_left" type="sphere" rgba="0.01568627450980392 0.5058823529411764 0.29411764705882354 0.5" contype="1" conaffinity="1" size="0.02392857142857143" />
              <inertial pos="0 0 0" mass="0.05" diaginertia="1.1451530612244902e-05 1.1451530612244902e-05 1.1451530612244902e-05" />
            </body>
          </body>
          <body name="Main_connection_1_L3Unit_front_left" pos="7.948877971858476e-18 0.0 0.24753868061375786" quat="0.6227565639103132 0.6227565639103133 0.33492426323964625 -0.3349242632396462">
            <geom name="Main_connection_1_L3Unit_vis0_front_left" type="cylinder" rgba="0.37254901960784315 0.5019607843137255 0.8352941176470589 0.9" contype="1" conaffinity="1" size="0.016 0.015" />
            <inertial pos="0 0 0" mass="0.1" diaginertia="0.00065 0.00065 0.0008" />
          </body>
        </body>
        <body name="Main_ground_GActuator_front_left" pos="0.0 0.03675000041723252 0.0" quat="0.0525919364819896 0.0525919364819895 0.7051482739233461 -0.705148273923346">
          <geom name="Main_ground_GActuator_vis0_front_left" type="cylinder" rgba="0.1568627450980392 0.42745098039215684 0.8 0.9" contype="1" conaffinity="1" size="0.048 0.02" />
          <inertial pos="0 0 0" mass="0.44" diaginertia="0.0067466666666666664 0.0067466666666666664 0.01056" />
        </body>
        <body name="Main_ground_GUnit_front_left" pos="0.0 0.0 0.0" quat="0.0525919364819896 0.0525919364819895 0.7051482739233461 -0.705148273923346">
          <geom name="Main_ground_GUnit_vis0_front_left" type="cylinder" rgba="0.1568627450980392 0.42745098039215684 0.8 0.9" contype="1" conaffinity="1" size="0.016750000417232513 0.016750000417232513" />
          <inertial pos="0 0 0" mass="0.1" diaginertia="0.0006979166840513548 0.0006979166840513548 0.0008375000208616257" />
        </body>
        <body name="L7_front_left" pos="-0.18000000000000002 0.0 0.06480000000000001" quat="-0.15086421372374947 6.976927370879126e-17 0.9885544947131214 6.976927370879126e-17">
          <joint name="Ground_connection_front_left" type="hinge" axis="0 1 0" range="-3.141592653589793 3.141592653589793" damping="0.1" />
          <geom name="L7_vis0_front_left" type="box" rgba="0.0 1.0 0.4666666666666667 1.0" contype="1" conaffinity="1" pos="-0.0 0.0 0.07543" quat="1.0 0.0 0.0 0.0" size="0.01675 0.01675 0.05868374576408096" />
          <inertial pos="-0.0 0.0 0.07543" mass="0.09523042750668785" diaginertia="0.00011822364017562971 0.00011822364017562971 1.7812057878230073e-05" />
          <body name="L6_front_left" pos="-5.551115123125783e-17 0.0 0.15086749152816192" quat="0.9908668077066263 0.0 -0.13484424120176491 0.0">
            <joint name="branch_2_front_left" type="hinge" axis="0 1 0" range="-3.141592653589793 3.141592653589793" damping="0.1" />
            <geom name="L6_vis0_front_left" type="box" rgba="0.0 0.8274509803921568 0.4196078431372549 1.0" contype="1" conaffinity="1" pos="0.0 0.0 0.11308" quat="1.0 0.0 0.0 0.0" size="0.01675 0.01675 0.09632924654860417" />
            <inertial pos="0.0 0.0 0.11308" mass="0.15632054857404132" diaginertia="0.0004981355538131413 0.0004981355538131413 2.9238455939536312e-05" />
            <body name="L5_front_left" pos="1.1102230246251565e-16 0.0 0.2261584930972083" quat="0.9221247588124448 0.0 -0.3868926584791841 0.0">
              <joint name="branch_1_front_left" type="hinge" axis="0 1 0" range="-3.141592653589793 3.141592653589793" damping="0.1" />
              <geom name="L5_vis0_front_left" type="box" rgba="0.0 0.6627450980392157 0.3607843137254902 1.0" contype="1" conaffinity="1" pos="-0.017313186151101806 0.0 0.22013287438567025" quat="0.9948405908123037 0.0 0.10145047497289715 0.0" size="0.016750000417232513 0.016750000417232513 0.06902079181415591" />
              <geom name="L5_vis1_front_left" type="box" rgba="0.0 0.6627450980392157 0.3607843137254902 1.0" contype="1" conaffinity="1" pos="-0.017313186151101806 0.0 0.06806381112821479" quat="0.12422055223167687 5.315175785701328e-17 0.9922546318376434 5.315175785701328e-17" size="0.016750000417232513 0.016750000417232513 0.053481251885428294" />
              <geom name="L5_vis2_front_left" type="box" rgba="0.0 0.6627450980392157 0.3607843137254902 1.0" contype="1" conaffinity="1" pos="0.0 0.0 0.15206906325745548" quat="1.0 0.0 0.0 0.0" size="0.016750000417232513 0.016750000417232513 0.13531906284022296" />
              <inertial pos="-0.01154 0.0 0.14676" mass="0.37744913378400663" diaginertia="0.11719219359867927 0.12293904243849035 0.005817447558393084" />
              <body name="branch_0_L5Pseudo_front_left" pos="-0.03462637230220361 0.0 0.13612762225642958" quat="1.0 0.0 0.0 0.0">
                <joint name="branch_0_L5_revolute_front_left" type="hinge" axis="0 1 0" range="-3.141592653589793 3.141592653589793" damping="0.1" />
                <geom name="branch_0_L5Pseudo_vis0_front_left" type="sphere" rgba="0.0 0.6627450980392157 0.3607843137254902 0.5" contype="1" conaffinity="1" size="0.02392857202461788" />
                <inertial pos="0 0 0" mass="0.05" diaginertia="1.145153118274651e-05 1.145153118274651e-05 1.145153118274651e-05" />
              </body>
              <body name="Main_connection_2_L5Pseudo_front_left" pos="0.0 0.0 0.30413812651491096" quat="1.0 0.0 0.0 0.0">
                <joint name="Main_connection_2_L5_revolute_front_left" type="hinge" axis="0 1 0" range="-3.141592653589793 3.141592653589793" damping="0.1" />
                <geom name="Main_connection_2_L5Pseudo_vis0_front_left" type="sphere" rgba="0.0 0.6627450980392157 0.3607843137254902 0.5" contype="1" conaffinity="1" size="0.02392857202461788" />
                <inertial pos="0 0 0" mass="0.05" diaginertia="1.145153118274651e-05 1.145153118274651e-05 1.145153118274651e-05" />
              </body>
            </body>
            <body name="branch_1_L6Unit_front_left" pos="1.1102230246251565e-16 0.0 0.2261584930972083" quat="0.6520406700562894 0.6520406700562893 -0.27357442240192215 0.273574422401922">
              <geom name="branch_1_L6Unit_vis0_front_left" type="cylinder" rgba="0.0 0.8274509803921568 0.4196078431372549 0.9" contype="1" conaffinity="1" size="0.016 0.015" />
              <inertial pos="0 0 0" mass="0.1" diaginertia="0.00065 0.00065 0.0008" />
            </body>
          </body>
          <body name="branch_2_L7Unit_front_left" pos="-5.551115123125783e-17 0.0 0.15086749152816192" quat="0.7006486389820223 0.7006486389820222 -0.09534927735772235 0.09534927735772233">
            <geom name="branch_2_L7Unit_vis0_front_left" type="cylinder" rgba="0.0 1.0 0.4666666666666667 0.9" contype="1" conaffinity="1" size="0.016 0.015" />
            <inertial pos="0 0 0" mass="0.1" diaginertia="0.00065 0.00065 0.0008" />
          </body>
        </body>
        <body name="Ground_connection_GActuator_front_left" pos="-0.18000000000000002 0.036750000000000005 0.06480000000000001" quat="-0.10667710856243973 -0.10667710856243982 0.6990135867840891 -0.6990135867840892">
          <geom name="Ground_connection_GActuator_vis0_front_left" type="cylinder" rgba="0.1568627450980392 0.42745098039215684 0.8 0.9" contype="1" conaffinity="1" size="0.048 0.02" />
          <inertial pos="0 0 0" mass="0.44" diaginertia="0.0067466666666666664 0.0067466666666666664 0.01056" />
        </body>
        <body name="Ground_connection_GUnit_front_left" pos="-0.18000000000000002 0.0 0.06480000000000001" quat="-0.10667710856243973 -0.10667710856243982 0.6990135867840891 -0.6990135867840892">
          <geom name="Ground_connection_GUnit_vis0_front_left" type="cylinder" rgba="0.1568627450980392 0.42745098039215684 0.8 0.9" contype="1" conaffinity="1" size="0.01675 0.01675" />
          <inertial pos="0 0 0" mass="0.1" diaginertia="0.0006979166666666668 0.0006979166666666668 0.0008375000000000001" />
        </body>
      </body>
      <body name="leg_rear_right" pos="-0.25 0.15 0">
        <geom name="G_vis0_rear_right" type="box" rgba="0.1568627450980392 0.42745098039215684 0.8 1.0" contype="1" conaffinity="1" pos="0.0 0.0 0.0" quat="1.0 0.0 0.0 0.0" size="0.0335 0.0335 0.0335" />
        <inertial pos="0.0 0.0 0.0" mass="0.04903493747122909" diaginertia="3.66863057180579e-05 3.66863057180579e-05 3.66863057180579e-05" />
        <body name="L3_rear_right" pos="0.0 0.0 0.0" quat="0.07437622984429398 5.650851124421949e-17 0.9972302524663743 5.650851124421949e-17">
          <joint name="Main_ground_rear_right" type="hinge" axis="0 1 0" range="-3.141592653589793 3.141592653589793" damping="0.1" />
          <geom name="L3_vis0_rear_right" type="box" rgba="0.37254901960784315 0.5019607843137255 0.8352941176470589 1.0" contype="1" conaffinity="1" pos="6.1321225795853815e-18 0.0 0.3057830760522891" quat="1.0 0.0 0.0 0.0" size="0.016750000417232513 0.016750000417232513 0.041494395021298744" />
          <geom name="L3_vis1_rear_right" type="box" rgba="0.37254901960784315 0.5019607843137255 0.8352941176470589 1.0" contype="1" conaffinity="1" pos="3.974438985929238e-18 0.0 0.12376934030687893" quat="1.0 0.0 0.0 0.0" size="0.016750000417232513 0.016750000417232513 0.10701933988964642" />
          <geom name="L3_vis2_rear_right" type="box" rgba="0.37254901960784315 0.5019607843137255 0.8352941176470589 1.0" contype="1" conaffinity="1" pos="2.1576835936561436e-18 0.0 0.1820137357454102" quat="1.0 0.0 0.0 0.0" size="0.016750000417232513 0.016750000417232513 0.16526373532817767" />
          <inertial pos="0.0 0.0 0.20386" mass="0.29536707186095634" diaginertia="0.046740090156920405 0.04702657912522108 0.0003417349201298814" />
          <body name="L4_rear_right" pos="4.315367187312287e-18 0.0 0.3640274714908204" quat="0.9889363528682975 0.0 0.14834045293024475 0.0">
            <joint name="Main_knee_rear_right" type="hinge" axis="0 1 0" range="-3.141592653589793 3.141592653589793" damping="0.1" />
            <geom name="L4_vis0_rear_right" type="box" rgba="0.5176470588235295 0.5843137254901961 0.8705882352941177 1.0" contype="1" conaffinity="1" pos="0.025481923004357435 0.0 0.26938032890320707" quat="0.13111872764660734 5.267499460431457e-17 0.9913666724579432 5.267499460431457e-17" size="0.016750000417232513 0.016750000417232513 0.08126739599789375" />
            <geom name="L4_vis1_rear_right" type="box" rgba="0.5176470588235295 0.5843137254901961 0.8705882352941177 1.0" contype="1" conaffinity="1" pos="6.938893903907228e-18 0.0 0.1820137357454102" quat="1.0 0.0 0.0 0.0" size="0.016750000417232513 0.016750000417232513 0.16526373532817767" />
            <geom name="L4_vis2_rear_right" type="box" rgba="0.5176470588235295 0.5843137254901961 0.8705882352941177 1.0" contype="1" conaffinity="1" pos="0.02548192300435744 0.0 0.08736659315779688" quat="0.1414213562373094 -5.195736337412961e-17 -0.9899494936611666 5.195736337412961e-17" size="0.016750000417232513 0.016750000417232513 0.07425686745547257" />
            <inertial pos="0.01699 0.0 0.17959" mass="0.5012590142024277" diaginertia="0.2619561188565024 0.26221491311633094 0.0003525505859475547" />
            <body name="EE_rear_right" pos="0.0 0.0 0.3640274714908204" quat="0.07437622984429398 5.650851124421949e-17 0.9972302524663743 5.650851124421949e-17">
              <geom name="EE_vis0_rear_right" type="sphere" rgba="0.6431372549019608 0.6666666666666666 0.9058823529411765 1.0" contype="1" conaffinity="1" pos="0.0 0.0 0.0" quat="1.0 0.0 0.0 0.0" size="0.002142857142857143" />
              <inertial pos="0.0 0.0 0.0" mass="2.979933439782622e-05" diaginertia="5.473347134294612e-11 5.473347134294612e-11 5.473347134294612e-11" />
            </body>
            <body name="Main_ee_L4Unit_rear_right" pos="0.0 0.0 0.3640274714908204" quat="0.0525919364819896 0.0525919364819895 0.7051482739233461 -0.705148273923346">
              <geom name="Main_ee_L4Unit_vis0_rear_right" type="cylinder" rgba="0.5176470588235295 0.5843137254901961 0.8705882352941177 0.9" contype="1" conaffinity="1" size="0.016 0.015" />
              <inertial pos="0 0 0" mass="0.1" diaginertia="0.00065 0.00065 0.0008" />
            </body>
            <body name="Main_connection_2_L4Pseudo_rear_right" pos="0.05096384600871484 0.0 0.17473318631559376" quat="0.8980331588121276 0.0 -0.4399277732468274 0.0">
              <geom name="Main_connection_2_L4Pseudo_vis0_rear_right" type="sphere" rgba="0.5176470588235295 0.5843137254901961 0.8705882352941177 0.5" contype="1" conaffinity="1" size="0.02392857202461788" />
              <inertial pos="0 0 0" mass="0.05" diaginertia="1.145153118274651e-05 1.145153118274651e-05 1.145153118274651e-05" />
            </body>
          </body>
          <body name="Main_knee_L3Unit_rear_right" pos="4.315367187312287e-18 0.0 0.3640274714908204" quat="0.6992836012750656 0.6992836012750655 0.10489254019125986 -0.10489254019125985">
            <geom name="Main_knee_L3Unit_vis0_rear_right" type="cylinder" rgba="0.37254901960784315 0.5019607843137255 0.8352941176470589 0.9" contype="1" conaffinity="1" size="0.016 0.015" />
            <inertial pos="0 0 0" mass="0.1" diaginertia="0.00065 0.00065 0.0008" />
          </body>
          <body name="L8_rear_right" pos="7.948877971858476e-18 0.0 0.24753868061375786" quat="0.8807107787388322 0.0 0.47365443544132435 0.0">
            <joint name="Main_connection_1_rear_right" type="hinge" axis="0 1 0" range="-3.141592653589793 3.141592653589793" damping="0.1" />
            <geom name="L8_vis0_rear_right" type="box" rgba="0.01568627450980392 0.5058823529411764 0.29411764705882354 1.0" contype="1" conaffinity="1" pos="-0.0 0.0 0.1009" quat="1.0 0.0 0.0 0.0" size="0.01675 0.01675 0.08415218035305282" />
            <inertial pos="-0.0 0.0 0.1009" mass="0.13655992824415478" diaginertia="0.0003351249810435438 0.0003351249810435438 2.554239657866712e-05" />
            <body name="branch_0_L8Pseudo_rear_right" pos="0.0 0.0 0.20180436070610566" quat="-0.6966608812115375 8.658629315504744e-17 0.717400597009484 8.658629315504744e-17">
              <geom name="branch_0_L8Pseudo_vis0_rear_right" type="sphere" rgba="0.01568627450980392 0.5058823529411764 0.29411764705882354 0.5" contype="1" conaffinity="1" size="0.02392857142857143" />
              <inertial pos="0 0 0" mass="0.05" diaginertia="1.1451530612244902e-05 1.1451530612244902e-05 1.1451530612244902e-05" />
            </body>
          </body>
          <body name="Main_connection_1_L3Unit_rear_right" pos="7.948877971858476e-18 0.0 0.24753868061375786" quat="0.6227565639103132 0.6227565639103133 0.33492426323964625 -0.3349242632396462">
            <geom name="Main_connection_1_L3Unit_vis0_rear_right" type="cylinder" rgba="0.37254901960784315 0.5019607843137255 0.8352941176470589 0.9" contype="1" conaffinity="1" size="0.016 0.015" />
            <inertial pos="0 0 0" mass="0.1" diaginertia="0.00065 0.00065 0.0008" />
          </body>
        </body>
        <body name="Main_ground_GActuator_rear_right" pos="0.0 0.03675000041723252 0.0" quat="0.0525919364819896 0.0525919364819895 0.7051482739233461 -0.705148273923346">
          <geom name="Main_ground_GActuator_vis0_rear_right" type="cylinder" rgba="0.1568627450980392 0.42745098039215684 0.8 0.9" contype="1" conaffinity="1" size="0.048 0.02" />
          <inertial pos="0 0 0" mass="0.44" diaginertia="0.0067466666666666664 0.0067466666666666664 0.01056" />
        </body>
        <body name="Main_ground_GUnit_rear_right" pos="0.0 0.0 0.0" quat="0.0525919364819896 0.0525919364819895 0.7051482739233461 -0.705148273923346">
          <geom name="Main_ground_GUnit_vis0_rear_right" type="cylinder" rgba="0.1568627450980392 0.42745098039215684 0.8 0.9" contype="1" conaffinity="1" size="0.016750000417232513 0.016750000417232513" />
          <inertial pos="0 0 0" mass="0.1" diaginertia="0.0006979166840513548 0.0006979166840513548 0.0008375000208616257" />
        </body>
        <body name="L7_rear_right" pos="-0.18000000000000002 0.0 0.06480000000000001" quat="-0.15086421372374947 6.976927370879126e-17 0.9885544947131214 6.976927370879126e-17">
          <joint name="Ground_connection_rear_right" type="hinge" axis="0 1 0" range="-3.141592653589793 3.141592653589793" damping="0.1" />
          <geom name="L7_vis0_rear_right" type="box" rgba="0.0 1.0 0.4666666666666667 1.0" contype="1" conaffinity="1" pos="-0.0 0.0 0.07543" quat="1.0 0.0 0.0 0.0" size="0.01675 0.01675 0.05868374576408096" />
          <inertial pos="-0.0 0.0 0.07543" mass="0.09523042750668785" diaginertia="0.00011822364017562971 0.00011822364017562971 1.7812057878230073e-05" />
          <body name="L6_rear_right" pos="-5.551115123125783e-17 0.0 0.15086749152816192" quat="0.9908668077066263 0.0 -0.13484424120176491 0.0">
            <joint name="branch_2_rear_right" type="hinge" axis="0 1 0" range="-3.141592653589793 3.141592653589793" damping="0.1" />
            <geom name="L6_vis0_rear_right" type="box" rgba="0.0 0.8274509803921568 0.4196078431372549 1.0" contype="1" conaffinity="1" pos="0.0 0.0 0.11308" quat="1.0 0.0 0.0 0.0" size="0.01675 0.01675 0.09632924654860417" />
            <inertial pos="0.0 0.0 0.11308" mass="0.15632054857404132" diaginertia="0.0004981355538131413 0.0004981355538131413 2.9238455939536312e-05" />
            <body name="L5_rear_right" pos="1.1102230246251565e-16 0.0 0.2261584930972083" quat="0.9221247588124448 0.0 -0.3868926584791841 0.0">
              <joint name="branch_1_rear_right" type="hinge" axis="0 1 0" range="-3.141592653589793 3.141592653589793" damping="0.1" />
              <geom name="L5_vis0_rear_right" type="box" rgba="0.0 0.6627450980392157 0.3607843137254902 1.0" contype="1" conaffinity="1" pos="-0.017313186151101806 0.0 0.22013287438567025" quat="0.9948405908123037 0.0 0.10145047497289715 0.0" size="0.016750000417232513 0.016750000417232513 0.06902079181415591" />
              <geom name="L5_vis1_rear_right" type="box" rgba="0.0 0.6627450980392157 0.3607843137254902 1.0" contype="1" conaffinity="1" pos="-0.017313186151101806 0.0 0.06806381112821479" quat="0.12422055223167687 5.315175785701328e-17 0.9922546318376434 5.315175785701328e-17" size="0.016750000417232513 0.016750000417232513 0.053481251885428294" />
              <geom name="L5_vis2_rear_right" type="box" rgba="0.0 0.6627450980392157 0.3607843137254902 1.0" contype="1" conaffinity="1" pos="0.0 0.0 0.15206906325745548" quat="1.0 0.0 0.0 0.0" size="0.016750000417232513 0.016750000417232513 0.13531906284022296" />
              <inertial pos="-0.01154 0.0 0.14676" mass="0.37744913378400663" diaginertia="0.11719219359867927 0.12293904243849035 0.005817447558393084" />
              <body name="branch_0_L5Pseudo_rear_right" pos="-0.03462637230220361 0.0 0.13612762225642958" quat="1.0 0.0 0.0 0.0">
                <joint name="branch_0_L5_revolute_rear_right" type="hinge" axis="0 1 0" range="-3.141592653589793 3.141592653589793" damping="0.1" />
                <geom name="branch_0_L5Pseudo_vis0_rear_right" type="sphere" rgba="0.0 0.6627450980392157 0.3607843137254902 0.5" contype="1" conaffinity="1" size="0.02392857202461788" />
                <inertial pos="0 0 0" mass="0.05" diaginertia="1.145153118274651e-05 1.145153118274651e-05 1.145153118274651e-05" />
              </body>
              <body name="Main_connection_2_L5Pseudo_rear_right" pos="0.0 0.0 0.30413812651491096" quat="1.0 0.0 0.0 0.0">
                <joint name="Main_connection_2_L5_revolute_rear_right" type="hinge" axis="0 1 0" range="-3.141592653589793 3.141592653589793" damping="0.1" />
                <geom name="Main_connection_2_L5Pseudo_vis0_rear_right" type="sphere" rgba="0.0 0.6627450980392157 0.3607843137254902 0.5" contype="1" conaffinity="1" size="0.02392857202461788" />
                <inertial pos="0 0 0" mass="0.05" diaginertia="1.145153118274651e-05 1.145153118274651e-05 1.145153118274651e-05" />
              </body>
            </body>
            <body name="branch_1_L6Unit_rear_right" pos="1.1102230246251565e-16 0.0 0.2261584930972083" quat="0.6520406700562894 0.6520406700562893 -0.27357442240192215 0.273574422401922">
              <geom name="branch_1_L6Unit_vis0_rear_right" type="cylinder" rgba="0.0 0.8274509803921568 0.4196078431372549 0.9" contype="1" conaffinity="1" size="0.016 0.015" />
              <inertial pos="0 0 0" mass="0.1" diaginertia="0.00065 0.00065 0.0008" />
            </body>
          </body>
          <body name="branch_2_L7Unit_rear_right" pos="-5.551115123125783e-17 0.0 0.15086749152816192" quat="0.7006486389820223 0.7006486389820222 -0.09534927735772235 0.09534927735772233">
            <geom name="branch_2_L7Unit_vis0_rear_right" type="cylinder" rgba="0.0 1.0 0.4666666666666667 0.9" contype="1" conaffinity="1" size="0.016 0.015" />
            <inertial pos="0 0 0" mass="0.1" diaginertia="0.00065 0.00065 0.0008" />
          </body>
        </body>
        <body name="Ground_connection_GActuator_rear_right" pos="-0.18000000000000002 0.036750000000000005 0.06480000000000001" quat="-0.10667710856243973 -0.10667710856243982 0.6990135867840891 -0.6990135867840892">
          <geom name="Ground_connection_GActuator_vis0_rear_right" type="cylinder" rgba="0.1568627450980392 0.42745098039215684 0.8 0.9" contype="1" conaffinity="1" size="0.048 0.02" />
          <inertial pos="0 0 0" mass="0.44" diaginertia="0.0067466666666666664 0.0067466666666666664 0.01056" />
        </body>
        <body name="Ground_connection_GUnit_rear_right" pos="-0.18000000000000002 0.0 0.06480000000000001" quat="-0.10667710856243973 -0.10667710856243982 0.6990135867840891 -0.6990135867840892">
          <geom name="Ground_connection_GUnit_vis0_rear_right" type="cylinder" rgba="0.1568627450980392 0.42745098039215684 0.8 0.9" contype="1" conaffinity="1" size="0.01675 0.01675" />
          <inertial pos="0 0 0" mass="0.1" diaginertia="0.0006979166666666668 0.0006979166666666668 0.0008375000000000001" />
        </body>
      </body>
      <body name="leg_rear_left" pos="-0.25 -0.15 0">
        <geom name="G_vis0_rear_left" type="box" rgba="0.1568627450980392 0.42745098039215684 0.8 1.0" contype="1" conaffinity="1" pos="0.0 0.0 0.0" quat="1.0 0.0 0.0 0.0" size="0.0335 0.0335 0.0335" />
        <inertial pos="0.0 0.0 0.0" mass="0.04903493747122909" diaginertia="3.66863057180579e-05 3.66863057180579e-05 3.66863057180579e-05" />
        <body name="L3_rear_left" pos="0.0 0.0 0.0" quat="0.07437622984429398 5.650851124421949e-17 0.9972302524663743 5.650851124421949e-17">
          <joint name="Main_ground_rear_left" type="hinge" axis="0 1 0" range="-3.141592653589793 3.141592653589793" damping="0.1" />
          <geom name="L3_vis0_rear_left" type="box" rgba="0.37254901960784315 0.5019607843137255 0.8352941176470589 1.0" contype="1" conaffinity="1" pos="6.1321225795853815e-18 0.0 0.3057830760522891" quat="1.0 0.0 0.0 0.0" size="0.016750000417232513 0.016750000417232513 0.041494395021298744" />
          <geom name="L3_vis1_rear_left" type="box" rgba="0.37254901960784315 0.5019607843137255 0.8352941176470589 1.0" contype="1" conaffinity="1" pos="3.974438985929238e-18 0.0 0.12376934030687893" quat="1.0 0.0 0.0 0.0" size="0.016750000417232513 0.016750000417232513 0.10701933988964642" />
          <geom name="L3_vis2_rear_left" type="box" rgba="0.37254901960784315 0.5019607843137255 0.8352941176470589 1.0" contype="1" conaffinity="1" pos="2.1576835936561436e-18 0.0 0.1820137357454102" quat="1.0 0.0 0.0 0.0" size="0.016750000417232513 0.016750000417232513 0.16526373532817767" />
          <inertial pos="0.0 0.0 0.20386" mass="0.29536707186095634" diaginertia="0.046740090156920405 0.04702657912522108 0.0003417349201298814" />
          <body name="L4_rear_left" pos="4.315367187312287e-18 0.0 0.3640274714908204" quat="0.9889363528682975 0.0 0.14834045293024475 0.0">
            <joint name="Main_knee_rear_left" type="hinge" axis="0 1 0" range="-3.141592653589793 3.141592653589793" damping="0.1" />
            <geom name="L4_vis0_rear_left" type="box" rgba="0.5176470588235295 0.5843137254901961 0.8705882352941177 1.0" contype="1" conaffinity="1" pos="0.025481923004357435 0.0 0.26938032890320707" quat="0.13111872764660734 5.267499460431457e-17 0.9913666724579432 5.267499460431457e-17" size="0.016750000417232513 0.016750000417232513 0.08126739599789375" />
            <geom name="L4_vis1_rear_left" type="box" rgba="0.5176470588235295 0.5843137254901961 0.8705882352941177 1.0" contype="1" conaffinity="1" pos="6.938893903907228e-18 0.0 0.1820137357454102" quat="1.0 0.0 0.0 0.0" size="0.016750000417232513 0.016750000417232513 0.16526373532817767" />
            <geom name="L4_vis2_rear_left" type="box" rgba="0.5176470588235295 0.5843137254901961 0.8705882352941177 1.0" contype="1" conaffinity="1" pos="0.02548192300435744 0.0 0.08736659315779688" quat="0.1414213562373094 -5.195736337412961e-17 -0.9899494936611666 5.195736337412961e-17" size="0.016750000417232513 0.016750000417232513 0.07425686745547257" />
            <inertial pos="0.01699 0.0 0.17959" mass="0.5012590142024277" diaginertia="0.2619561188565024 0.26221491311633094 0.0003525505859475547" />
            <body name="EE_rear_left" pos="0.0 0.0 0.3640274714908204" quat="0.07437622984429398 5.650851124421949e-17 0.9972302524663743 5.650851124421949e-17">
              <geom name="EE_vis0_rear_left" type="sphere" rgba="0.6431372549019608 0.6666666666666666 0.9058823529411765 1.0" contype="1" conaffinity="1" pos="0.0 0.0 0.0" quat="1.0 0.0 0.0 0.0" size="0.002142857142857143" />
              <inertial pos="0.0 0.0 0.0" mass="2.979933439782622e-05" diaginertia="5.473347134294612e-11 5.473347134294612e-11 5.473347134294612e-11" />
            </body>
            <body name="Main_ee_L4Unit_rear_left" pos="0.0 0.0 0.3640274714908204" quat="0.0525919364819896 0.0525919364819895 0.7051482739233461 -0.705148273923346">
              <geom name="Main_ee_L4Unit_vis0_rear_left" type="cylinder" rgba="0.5176470588235295 0.5843137254901961 0.8705882352941177 0.9" contype="1" conaffinity="1" size="0.016 0.015" />
              <inertial pos="0 0 0" mass="0.1" diaginertia="0.00065 0.00065 0.0008" />
            </body>
            <body name="Main_connection_2_L4Pseudo_rear_left" pos="0.05096384600871484 0.0 0.17473318631559376" quat="0.8980331588121276 0.0 -0.4399277732468274 0.0">
              <geom name="Main_connection_2_L4Pseudo_vis0_rear_left" type="sphere" rgba="0.5176470588235295 0.5843137254901961 0.8705882352941177 0.5" contype="1" conaffinity="1" size="0.02392857202461788" />
              <inertial pos="0 0 0" mass="0.05" diaginertia="1.145153118274651e-05 1.145153118274651e-05 1.145153118274651e-05" />
            </body>
          </body>
          <body name="Main_knee_L3Unit_rear_left" pos="4.315367187312287e-18 0.0 0.3640274714908204" quat="0.6992836012750656 0.6992836012750655 0.10489254019125986 -0.10489254019125985">
            <geom name="Main_knee_L3Unit_vis0_rear_left" type="cylinder" rgba="0.37254901960784315 0.5019607843137255 0.8352941176470589 0.9" contype="1" conaffinity="1" size="0.016 0.015" />
            <inertial pos="0 0 0" mass="0.1" diaginertia="0.00065 0.00065 0.0008" />
          </body>
          <body name="L8_rear_left" pos="7.948877971858476e-18 0.0 0.24753868061375786" quat="0.8807107787388322 0.0 0.47365443544132435 0.0">
            <joint name="Main_connection_1_rear_left" type="hinge" axis="0 1 0" range="-3.141592653589793 3.141592653589793" damping="0.1" />
            <geom name="L8_vis0_rear_left" type="box" rgba="0.01568627450980392 0.5058823529411764 0.29411764705882354 1.0" contype="1" conaffinity="1" pos="-0.0 0.0 0.1009" quat="1.0 0.0 0.0 0.0" size="0.01675 0.01675 0.08415218035305282" />
            <inertial pos="-0.0 0.0 0.1009" mass="0.13655992824415478" diaginertia="0.0003351249810435438 0.0003351249810435438 2.554239657866712e-05" />
            <body name="branch_0_L8Pseudo_rear_left" pos="0.0 0.0 0.20180436070610566" quat="-0.6966608812115375 8.658629315504744e-17 0.717400597009484 8.658629315504744e-17">
              <geom name="branch_0_L8Pseudo_vis0_rear_left" type="sphere" rgba="0.01568627450980392 0.5058823529411764 0.29411764705882354 0.5" contype="1" conaffinity="1" size="0.02392857142857143" />
              <inertial pos="0 0 0" mass="0.05" diaginertia="1.1451530612244902e-05 1.1451530612244902e-05 1.1451530612244902e-05" />
            </body>
          </body>
          <body name="Main_connection_1_L3Unit_rear_left" pos="7.948877971858476e-18 0.0 0.24753868061375786" quat="0.6227565639103132 0.6227565639103133 0.33492426323964625 -0.3349242632396462">
            <geom name="Main_connection_1_L3Unit_vis0_rear_left" type="cylinder" rgba="0.37254901960784315 0.5019607843137255 0.8352941176470589 0.9" contype="1" conaffinity="1" size="0.016 0.015" />
            <inertial pos="0 0 0" mass="0.1" diaginertia="0.00065 0.00065 0.0008" />
          </body>
        </body>
        <body name="Main_ground_GActuator_rear_left" pos="0.0 0.03675000041723252 0.0" quat="0.0525919364819896 0.0525919364819895 0.7051482739233461 -0.705148273923346">
          <geom name="Main_ground_GActuator_vis0_rear_left" type="cylinder" rgba="0.1568627450980392 0.42745098039215684 0.8 0.9" contype="1" conaffinity="1" size="0.048 0.02" />
          <inertial pos="0 0 0" mass="0.44" diaginertia="0.0067466666666666664 0.0067466666666666664 0.01056" />
        </body>
        <body name="Main_ground_GUnit_rear_left" pos="0.0 0.0 0.0" quat="0.0525919364819896 0.0525919364819895 0.7051482739233461 -0.705148273923346">
          <geom name="Main_ground_GUnit_vis0_rear_left" type="cylinder" rgba="0.1568627450980392 0.42745098039215684 0.8 0.9" contype="1" conaffinity="1" size="0.016750000417232513 0.016750000417232513" />
          <inertial pos="0 0 0" mass="0.1" diaginertia="0.0006979166840513548 0.0006979166840513548 0.0008375000208616257" />
        </body>
        <body name="L7_rear_left" pos="-0.18000000000000002 0.0 0.06480000000000001" quat="-0.15086421372374947 6.976927370879126e-17 0.9885544947131214 6.976927370879126e-17">
          <joint name="Ground_connection_rear_left" type="hinge" axis="0 1 0" range="-3.141592653589793 3.141592653589793" damping="0.1" />
          <geom name="L7_vis0_rear_left" type="box" rgba="0.0 1.0 0.4666666666666667 1.0" contype="1" conaffinity="1" pos="-0.0 0.0 0.07543" quat="1.0 0.0 0.0 0.0" size="0.01675 0.01675 0.05868374576408096" />
          <inertial pos="-0.0 0.0 0.07543" mass="0.09523042750668785" diaginertia="0.00011822364017562971 0.00011822364017562971 1.7812057878230073e-05" />
          <body name="L6_rear_left" pos="-5.551115123125783e-17 0.0 0.15086749152816192" quat="0.9908668077066263 0.0 -0.13484424120176491 0.0">
            <joint name="branch_2_rear_left" type="hinge" axis="0 1 0" range="-3.141592653589793 3.141592653589793" damping="0.1" />
            <geom name="L6_vis0_rear_left" type="box" rgba="0.0 0.8274509803921568 0.4196078431372549 1.0" contype="1" conaffinity="1" pos="0.0 0.0 0.11308" quat="1.0 0.0 0.0 0.0" size="0.01675 0.01675 0.09632924654860417" />
            <inertial pos="0.0 0.0 0.11308" mass="0.15632054857404132" diaginertia="0.0004981355538131413 0.0004981355538131413 2.9238455939536312e-05" />
            <body name="L5_rear_left" pos="1.1102230246251565e-16 0.0 0.2261584930972083" quat="0.9221247588124448 0.0 -0.3868926584791841 0.0">
              <joint name="branch_1_rear_left" type="hinge" axis="0 1 0" range="-3.141592653589793 3.141592653589793" damping="0.1" />
              <geom name="L5_vis0_rear_left" type="box" rgba="0.0 0.6627450980392157 0.3607843137254902 1.0" contype="1" conaffinity="1" pos="-0.017313186151101806 0.0 0.22013287438567025" quat="0.9948405908123037 0.0 0.10145047497289715 0.0" size="0.016750000417232513 0.016750000417232513 0.06902079181415591" />
              <geom name="L5_vis1_rear_left" type="box" rgba="0.0 0.6627450980392157 0.3607843137254902 1.0" contype="1" conaffinity="1" pos="-0.017313186151101806 0.0 0.06806381112821479" quat="0.12422055223167687 5.315175785701328e-17 0.9922546318376434 5.315175785701328e-17" size="0.016750000417232513 0.016750000417232513 0.053481251885428294" />
              <geom name="L5_vis2_rear_left" type="box" rgba="0.0 0.6627450980392157 0.3607843137254902 1.0" contype="1" conaffinity="1" pos="0.0 0.0 0.15206906325745548" quat="1.0 0.0 0.0 0.0" size="0.016750000417232513 0.016750000417232513 0.13531906284022296" />
              <inertial pos="-0.01154 0.0 0.14676" mass="0.37744913378400663" diaginertia="0.11719219359867927 0.12293904243849035 0.005817447558393084" />
              <body name="branch_0_L5Pseudo_rear_left" pos="-0.03462637230220361 0.0 0.13612762225642958" quat="1.0 0.0 0.0 0.0">
                <joint name="branch_0_L5_revolute_rear_left" type="hinge" axis="0 1 0" range="-3.141592653589793 3.141592653589793" damping="0.1" />
                <geom name="branch_0_L5Pseudo_vis0_rear_left" type="sphere" rgba="0.0 0.6627450980392157 0.3607843137254902 0.5" contype="1" conaffinity="1" size="0.02392857202461788" />
                <inertial pos="0 0 0" mass="0.05" diaginertia="1.145153118274651e-05 1.145153118274651e-05 1.145153118274651e-05" />
              </body>
              <body name="Main_connection_2_L5Pseudo_rear_left" pos="0.0 0.0 0.30413812651491096" quat="1.0 0.0 0.0 0.0">
                <joint name="Main_connection_2_L5_revolute_rear_left" type="hinge" axis="0 1 0" range="-3.141592653589793 3.141592653589793" damping="0.1" />
                <geom name="Main_connection_2_L5Pseudo_vis0_rear_left" type="sphere" rgba="0.0 0.6627450980392157 0.3607843137254902 0.5" contype="1" conaffinity="1" size="0.02392857202461788" />
                <inertial pos="0 0 0" mass="0.05" diaginertia="1.145153118274651e-05 1.145153118274651e-05 1.145153118274651e-05" />
              </body>
            </body>
            <body name="branch_1_L6Unit_rear_left" pos="1.1102230246251565e-16 0.0 0.2261584930972083" quat="0.6520406700562894 0.6520406700562893 -0.27357442240192215 0.273574422401922">
              <geom name="branch_1_L6Unit_vis0_rear_left" type="cylinder" rgba="0.0 0.8274509803921568 0.4196078431372549 0.9" contype="1" conaffinity="1" size="0.016 0.015" />
              <inertial pos="0 0 0" mass="0.1" diaginertia="0.00065 0.00065 0.0008" />
            </body>
          </body>
          <body name="branch_2_L7Unit_rear_left" pos="-5.551115123125783e-17 0.0 0.15086749152816192" quat="0.7006486389820223 0.7006486389820222 -0.09534927735772235 0.09534927735772233">
            <geom name="branch_2_L7Unit_vis0_rear_left" type="cylinder" rgba="0.0 1.0 0.4666666666666667 0.9" contype="1" conaffinity="1" size="0.016 0.015" />
            <inertial pos="0 0 0" mass="0.1" diaginertia="0.00065 0.00065 0.0008" />
          </body>
        </body>
        <body name="Ground_connection_GActuator_rear_left" pos="-0.18000000000000002 0.036750000000000005 0.06480000000000001" quat="-0.10667710856243973 -0.10667710856243982 0.6990135867840891 -0.6990135867840892">
          <geom name="Ground_connection_GActuator_vis0_rear_left" type="cylinder" rgba="0.1568627450980392 0.42745098039215684 0.8 0.9" contype="1" conaffinity="1" size="0.048 0.02" />
          <inertial pos="0 0 0" mass="0.44" diaginertia="0.0067466666666666664 0.0067466666666666664 0.01056" />
        </body>
        <body name="Ground_connection_GUnit_rear_left" pos="-0.18000000000000002 0.0 0.06480000000000001" quat="-0.10667710856243973 -0.10667710856243982 0.6990135867840891 -0.6990135867840892">
          <geom name="Ground_connection_GUnit_vis0_rear_left" type="cylinder" rgba="0.1568627450980392 0.42745098039215684 0.8 0.9" contype="1" conaffinity="1" size="0.01675 0.01675" />
          <inertial pos="0 0 0" mass="0.1" diaginertia="0.0006979166666666668 0.0006979166666666668 0.0008375000000000001" />
        </body>
      </body>
    </body>
  </worldbody>
  <actuator>
    <motor name="Main_ground_motor_front_right" joint="Main_ground_front_right" gear="80" ctrlrange="-1.0 1.0" forcerange="-20 20" />
    <motor name="Ground_connection_motor_front_right" joint="Ground_connection_front_right" gear="80" ctrlrange="-1.0 1.0" forcerange="-20 20" />
    <motor name="Main_ground_motor_front_left" joint="Main_ground_front_left" gear="80" ctrlrange="-1.0 1.0" forcerange="-20 20" />
    <motor name="Ground_connection_motor_front_left" joint="Ground_connection_front_left" gear="80" ctrlrange="-1.0 1.0" forcerange="-20 20" />
    <motor name="Main_ground_motor_rear_right" joint="Main_ground_rear_right" gear="80" ctrlrange="-1.0 1.0" forcerange="-20 20" />
    <motor name="Ground_connection_motor_rear_right" joint="Ground_connection_rear_right" gear="80" ctrlrange="-1.0 1.0" forcerange="-20 20" />
    <motor name="Main_ground_motor_rear_left" joint="Main_ground_rear_left" gear="80" ctrlrange="-1.0 1.0" forcerange="-20 20" />
    <motor name="Ground_connection_motor_rear_left" joint="Ground_connection_rear_left" gear="80" ctrlrange="-1.0 1.0" forcerange="-20 20" />
  </actuator>
  <equality>
    <connect name="connect_branch_0_L5Pseudo_to_branch_0_L8Pseudo_front_right" body1="branch_0_L5Pseudo_front_right" body2="branch_0_L8Pseudo_front_right" anchor="0 0 0" solref="0.01 1" />
    <connect name="connect_Main_connection_2_L5Pseudo_to_Main_connection_2_L4Pseudo_front_right" body1="Main_connection_2_L5Pseudo_front_right" body2="Main_connection_2_L4Pseudo_front_right" anchor="0 0 0" solref="0.01 1" />
    <connect name="connect_branch_0_L5Pseudo_to_branch_0_L8Pseudo_front_left" body1="branch_0_L5Pseudo_front_left" body2="branch_0_L8Pseudo_front_left" anchor="0 0 0" solref="0.01 1" />
    <connect name="connect_Main_connection_2_L5Pseudo_to_Main_connection_2_L4Pseudo_front_left" body1="Main_connection_2_L5Pseudo_front_left" body2="Main_connection_2_L4Pseudo_front_left" anchor="0 0 0" solref="0.01 1" />
    <connect name="connect_branch_0_L5Pseudo_to_branch_0_L8Pseudo_rear_right" body1="branch_0_L5Pseudo_rear_right" body2="branch_0_L8Pseudo_rear_right" anchor="0 0 0" solref="0.01 1" />
    <connect name="connect_Main_connection_2_L5Pseudo_to_Main_connection_2_L4Pseudo_rear_right" body1="Main_connection_2_L5Pseudo_rear_right" body2="Main_connection_2_L4Pseudo_rear_right" anchor="0 0 0" solref="0.01 1" />
    <connect name="connect_branch_0_L5Pseudo_to_branch_0_L8Pseudo_rear_left" body1="branch_0_L5Pseudo_rear_left" body2="branch_0_L8Pseudo_rear_left" anchor="0 0 0" solref="0.01 1" />
    <connect name="connect_Main_connection_2_L5Pseudo_to_Main_connection_2_L4Pseudo_rear_left" body1="Main_connection_2_L5Pseudo_rear_left" body2="Main_connection_2_L4Pseudo_rear_left" anchor="0 0 0" solref="0.01 1" />
  </equality>
</mujoco>